Workbook

Sheet RECAP
A1: ANNO | B1: MESE | C1: USCITE | D1: ENTRATE | E1: RISPARMIATI | F1: INVESTITI | G1: IMPREVISTI
A2: 2022 | B2: Maggio | C2: 530 | D2: 905 | E2: =D2-C2-G2 -> 375 | F2: 0 | G2: 0
A3: 2022 | B3: Giugno | C3: 512 | D3: 957.67 | E3: =D3-C3-G3 -> 445.67 | F3: 0 | G3: 0
A4: 2022 | B4: luglio | C4: 551.68 | D4: 1034.48 | E4: =D4-C4-G4 -> 482.8 | F4: 0 | G4: 0
A5: 2022 | B5: agosto | C5: 1754.45 | D5: 1399.42 | E5: =D5-C5-G5 -> -723.23 | F5: 0 | G5: 368.2
A6: 2022 | B6: settembre | C6: 656.94 | D6: 1735.5 | E6: =D6-C6-G6 -> -1048.44 | F6: 0 | G6: 2127
A7: 2022 | B7: ottobre | C7: 771 | D7: 1960 | E7: =D7-C7-G7 -> 1189 | F7: 0 | G7: 0
A8: 2022 | B8: novembre | C8: 1162.28 | D8: 1577 | E8: =D8-C8-G8 -> 414.72 | F8: 0 | G8: 0
A9: 2022 | B9: dicembre | C9: 1071.17 | D9: 3450 | E9: =D9-C9-G9 -> 728.83 | F9: 0 | G9: 1650
A10: 2023 | B10: gennaio | C10: 1748.15 | D10: 2701 | E10: 952.85 | F10: 0 | G10: 0
A11: 2023 | B11: febbraio | C11: 3829.48 | D11: 2020 | E11: -1809.48 | F11: 0 | G11: 1600
A12: 2023 | B12: marzo | C12: 1074.29 | D12: 2081.5 | E12: 1007.21 | F12: 0 | G12: 0
A13: 2023 | B13: aprile | C13: 1401.68 | D13: 2095.17 | E13: 693.49 | F13: 0 | G13: 0
A14: 2023 | B14: maggio | C14: 1191.37 | D14: 2158.3 | E14: 966.93 | F14: 0 | G14: 0
A15: 2023 | B15: giugno | C15: 2683.74 | D15: 2324.7 | E15: -359.04 | F15: 1000 | G15: 0
A16: 2023 | B16: luglio | C16: 2875.04 | D16: 2440.26 | E16: -434.78 | F16: 0 | G16: 0
A17: 2023 | B17: agosto | C17: 2034.22 | D17: 1848.9 | E17: -185.32 | F17: 0 | G17: 0
A18: 2023 | B18: settembre | C18: 2326.23 | D18: 1835.1 | E18: -491.13 | F18: 0 | G18: 100
A19: 2023 | B19: ottobre | C19: 1562.22 | D19: 1817 | E19: 254.78 | F19: 0 | G19: 0
A20: 2023 | B20: novembre | C20: 1253.83 | D20: 1899.76 | E20: 645.93 | F20: 0 | G20: 0
A21: 2023 | B21: dicembre | C21: 2064.51 | D21: 3621.24 | E21: 1556.73 | F21: 0 | G21: 0
... A57: 2026 | B57: dicembre | C57: 0 | D57: 0 | E57: 0 | F57: 0 | G57: 0
B58: gennaio
B59: febbraio
B60: marzo
B61: aprile

Sheet SPESE
A1: MESE | B1: ANNO | C1: BAR | D1: REGAZ | E1: ELISA | F1: LAVORO | G1: ABBIGLIAMENTO | H1: VIAGGI | I1: GITE | J1: SPORT | K1: AUTO | L1: BENZINA | M1: FORMAZIONE | N1: CHIAVE | O1: CURA | P1: SALUTE | Q1: REGALI | R1: CASA | S1: AFFITTO | T1: ABBONAMENTI | U1: CONTO DEPOSIT | V1: OBBLIGAZIONI | W1: AZIONARIO | X1: IMPREVISTI | Y1: ALTRO | Z1: DEBITO | AA1: TOTALE
A2: gennaio | B2: 2023 | C2: 4.5 | D2: 66.8 | E2: 36.4 | F2: 14.5 | G2: 382.95 | H2: 381 | I2: 30 | J2: 0 | K2: 505 | L2: 200 | N2: 22 | Q2: 105 | R2: 0 | S2: 0 | T2: 0 | V2: 0 | W2: 0 | X2: 0 | Y2: 0 | Z2: 0 | AA2: =SUM(C2:Z2) -> 1748.15
A3: febbraio | B3: 2023 | C3: 4 | D3: 98.9 | E3: 38.1 | F3: 9.03 | G3: 129.99 | H3: 1086.76 | I3: 28.3 | J3: 54 | K3: 500 | L3: 222.5 | N3: 20 | O3: 20 | P3: 4.9 | Q3: 13 | R3: 0 | S3: 0 | T3: 0 | V3: 0 | W3: 0 | X3: 1600 | Y3: 0 | Z3: 0 | AA3: =SUM(C3:Z3) -> 3829.48
A4: marzo | B4: 2023 | C4: 3.8 | D4: 70.6 | E4: 39.4 | F4: 12.35 | G4: 20 | H4: 0 | I4: 0 | J4: 22 | K4: 500 | L4: 151.99 | M4: 15.2 | N4: 20 | O4: 23 | P4: 105.05 | Q4: 25 | R4: 0 | S4: 0 | T4: 0 | V4: 0 | W4: 0 | X4: 0 | Y4: 65.9 | Z4: 0 | AA4: =SUM(C4:Z4) -> 1074.29
A5: aprile | B5: 2023 | C5: 3.7 | D5: 141.8 | E5: 118.85 | F5: 5 | G5: 292.05 | H5: 0 | I5: 18.53 | J5: 15 | K5: 500 | L5: 198.96 | N5: 30 | O5: 0 | P5: 0 | Q5: 46.99 | R5: 0 | S5: 0 | T5: 0 | V5: 0 | W5: 0 | X5: 0 | Y5: 30.8 | Z5: 0 | AA5: =SUM(C5:Z5) -> 1401.68
A6: maggio | B6: 2023 | C6: 2.5 | D6: 71.2 | E6: 60.55 | F6: 15.85 | G6: 41.5 | H6: 0 | I6: 0 | J6: 7 | K6: 758.97 | L6: 118.8 | N6: 20 | O6: 0 | P6: 28.5 | Q6: 10 | R6: 0 | S6: 0 | T6: 0 | V6: 0 | W6: 0 | X6: 0 | Y6: 56.5 | Z6: 0 | AA6: =SUM(C6:Z6) -> 1191.37
A7: giugno | B7: 2023 | C7: 2.5 | D7: 128.5 | E7: 35 | F7: 2.8 | G7: 125.3 | H7: 0 | I7: 0 | J7: 16 | K7: 500 | L7: 92.95 | N7: 10 | O7: 20 | P7: 0 | Q7: 15 | R7: 0 | S7: 0 | T7: 5.99 | V7: 1000 | W7: 0 | X7: 0 | Y7: 729.7 | Z7: 0 | AA7: =SUM(C7:Z7) -> 2683.74
A8: luglio | B8: 2023 | C8: 5.5 | D8: 35.9 | E8: 46.9 | F8: 4.35 | G8: 18.8 | H8: 1895.1 | I8: 0 | J8: 23.5 | K8: 500 | L8: 204 | N8: 30 | O8: 0 | P8: 0 | Q8: 0 | R8: 0 | S8: 0 | T8: 5.99 | V8: 0 | W8: 0 | X8: 0 | Y8: 105 | Z8: 0 | AA8: =SUM(C8:Z8) -> 2875.04
A9: agosto | B9: 2023 | C9: 15 | D9: 54.8 | E9: 61.5 | F9: 3.1 | G9: 210.41 | H9: 1005.83 | I9: 0 | J9: 17 | K9: 500 | L9: 48.8 | N9: 30 | O9: 23 | P9: 0 | Q9: 25 | R9: 0 | S9: 0 | T9: 30.99 | V9: 0 | W9: 0 | X9: 0 | Y9: 8.79 | Z9: 0 | AA9: =SUM(C9:Z9) -> 2034.22
A10: settembre | B10: 2023 | C10: 19.1 | D10: 82 | E10: 63.74 | F10: 7 | G10: 197 | H10: 0 | I10: 0 | J10: 49.69 | K10: 1592 | L10: 154.31 | N10: 10 | O10: 0 | P10: 0 | Q10: 10 | R10: 0 | S10: 0 | T10: 5.99 | V10: 0 | W10: 0 | X10: 100 | Y10: 35.4 | Z10: 0 | AA10: =SUM(C10:Z10) -> 2326.23
A11: ottobre | B11: 2023 | C11: 0 | D11: 89.6 | E11: 69.3 | F11: 7.25 | G11: 31 | H11: 467.08 | I11: 7.2 | J11: 15 | K11: 500 | L11: 188 | N11: 30 | O11: 0 | P11: 29.5 | Q11: 77.3 | R11: 0 | S11: 0 | T11: 5.99 | V11: 0 | W11: 0 | X11: 0 | Y11: 45 | Z11: 0 | AA11: =SUM(C11:Z11) -> 1562.22
A12: novembre | B12: 2023 | C12: 2.3 | D12: 92.7 | E12: 40 | F12: 25.5 | G12: 211.66 | H12: 0 | I12: 8.8 | J12: 45.3 | K12: 500 | L12: 148.08 | N12: 10 | O12: 15 | P12: 21 | Q12: 0 | R12: 0 | S12: 0 | T12: 5.99 | V12: 0 | W12: 0 | X12: 0 | Y12: 127.5 | Z12: 0 | AA12: =SUM(C12:Z12) -> 1253.83
A13: dicembre | B13: 2023 | C13: 3 | D13: 168.2 | E13: 0 | F13: 27 | G13: 0 | H13: 585.4 | I13: 161 | J13: 8.6 | K13: 500 | L13: 186 | N13: 20 | O13: 23 | P13: 0 | Q13: 314.55 | R13: 0 | S13: 0 | T13: 5.99 | V13: 0 | W13: 0 | X13: 0 | Y13: 61.77 | Z13: 0 | AA13: =SUM(C13:Z13) -> 2064.51
A14: Totale anno | B14: 2023 | C14: =SUM(C2:C13) -> 65.9 | D14: =SUM(D2:D13) -> 1101 | E14: =SUM(E2:E13) -> 609.74 | F14: =SUM(F2:F13) -> 133.73 | G14: =SUM(G2:G13) -> 1660.66 | H14: =SUM(H2:H13) -> 5421.17 | I14: =SUM(I2:I13) -> 253.83 | J14: =SUM(J2:J13) -> 273.09 | ... Z14: =SUM(Z2:Z13) -> 0 | AA14: =SUM(C14:Z14) -> 24044.76
A15: gennaio | B15: 2024 | C15: 1.1 | D15: 95.65 | E15: 62.5 | F15: 8.5 | G15: 55.38 | H15: 95 | I15: 200.07 | J15: 23.6 | K15: 500 | L15: 147 | N15: 30 | Q15: 43.23 | R15: 0 | S15: 0 | T15: 5.99 | V15: 0 | W15: 0 | X15: 624.5 | Y15: 26 | Z15: 0 | AA15: =SUM(C15:Z15) -> 1918.52
A16: febbraio | B16: 2024 | C16: 3.6 | D16: 127 | E16: 23 | F16: 16.4 | G16: 10 | H16: 271.07 | I16: 0 | J16: 17 | K16: 500 | L16: 162.7 | N16: 20 | O16: 20 | P16: 47 | Q16: 10 | R16: 0 | S16: 0 | T16: 5.99 | V16: 0 | W16: 200 | X16: 0 | Y16: 92.39 | Z16: 0 | AA16: =SUM(C16:Z16) -> 1526.15
A17: marzo | B17: 2024 | C17: 8.4 | D17: 136.4 | E17: 76.4 | F17: 5.4 | G17: 374.22 | H17: 0 | I17: 0 | J17: 27 | K17: 502.5 | L17: 147.1 | M17: 0 | N17: 20 | O17: 0 | P17: 65.89 | Q17: 10 | R17: 0 | S17: 0 | T17: 5.99 | V17: 0 | W17: 100 | X17: 10 | Y17: 275 | Z17: 0 | AA17: =SUM(C17:Z17) -> 1764.3
A18: aprile | B18: 2024 | C18: 3.6 | D18: 108.53 | E18: 41.8 | F18: 19.8 | G18: 83.14 | H18: 1351.46 | I18: 0 | J18: 14 | K18: 500 | L18: 121 | N18: 10 | O18: 15 | P18: 0 | R18: 336.64 | S18: 325 | T18: 0 | V18: 0 | W18: 200 | X18: 0 | Y18: 1020.5 | Z18: 0 | AA18: =SUM(C18:Z18) -> 4150.47
A19: maggio | B19: 2024 | C19: 6.6 | D19: 98.8 | E19: 29 | G19: 82.49 | H19: 0 | I19: 0 | J19: 52.5 | K19: 760.7 | L19: 145.04 | N19: 20 | O19: 20 | Q19: 281.5 | R19: 363.11 | S19: 0 | T19: 5.99 | V19: 0 | W19: 200 | X19: 85 | Y19: 128.9 | Z19: 0 | AA19: =SUM(C19:Z19) -> 2279.63
A20: giugno | B20: 2024 | D20: 137.05 | E20: 0 | G20: 101.34 | H20: 40.13 | I20: 0 | J20: 15.5 | K20: 500 | L20: 98.7 | N20: 20 | P20: 0 | R20: 257.28 | S20: 0 | T20: 16.99 | V20: 0 | W20: 100 | X20: 47.29 | Y20: 76.2 | Z20: 0 | AA20: =SUM(C20:Z20) -> 1410.48
A21: luglio | B21: 2024 | D21: 127.5 | E21: 27 | G21: 147.16 | H21: 331.8 | I21: 0 | J21: 21 | K21: 503 | L21: 153.49 | N21: 30 | O21: 0 | P21: 65 | Q21: 100 | R21: 365.5 | S21: 0 | T21: 5.99 | V21: 0 | W21: 100 | X21: 0 | Y21: 212.22 | Z21: 0 | AA21: =SUM(C21:Z21) -> 2189.66
A22: agosto | B22: 2024 | C22: 5.6 | D22: 56.2 | E22: 6 | G22: 19.48 | H22: 341.24 | I22: 0 | J22: 10 | K22: 579 | L22: 72.49 | N22: 20 | P22: 0 | Q22: 40 | R22: 80.83 | S22: 0 | T22: 55.89 | V22: 0 | W22: 100 | X22: 200 | Y22: 20 | Z22: 0 | AA22: =SUM(C22:Z22) -> 1606.73
A23: settembre | B23: 2024 | D23: 37.3 | E23: 6.1 | G23: 0 | H23: 93.98 | I23: 0 | J23: 0 | K23: 1058 | L23: 71.9 | N23: 20 | O23: 0 | P23: 0 | R23: 327.29 | S23: 0 | T23: 5.99 | V23: 0 | W23: 200 | X23: 0 | Y23: 0 | Z23: 0 | AA23: =SUM(C23:Z23) -> 1820.56
A24: ottobre | B24: 2024 | C24: 1.2 | D24: 78 | E24: 8 | G24: 125.28 | H24: 1584.26 | I24: 0 | J24: 86.48 | K24: 500 | L24: 68.99 | N24: 34.8 | O24: 0 | Q24: 50 | R24: 10.45 | S24: 325 | T24: 10 | V24: 0 | W24: 0 | X24: 0 | Y24: 53.7 | Z24: 0 | AA24: =SUM(C24:Z24) -> 2936.16
A25: novembre | B25: 2024 | C25: 3.7 | D25: 87 | E25: 6 | F25: 16.3 | G25: 132.09 | H25: 91.85 | I25: 94.2 | J25: 38 | K25: 523 | L25: 143.5 | N25: 2.2 | O25: 18 | Q25: 0 | R25: 27 | S25: 325 | T25: 5.99 | V25: 0 | W25: 360 | X25: 0 | Y25: 42 | Z25: 0 | AA25: =SUM(C25:Z25) -> 1915.83
A26: dicembre | B26: 2024 | C26: 2.6 | D26: 39 | E26: 0 | G26: 0 | H26: 1045.83 | I26: 0 | J26: 0 | K26: 503 | L26: 82 | N26: 18.8 | O26: 18 | P26: 207 | Q26: 306 | R26: 0 | S26: 162.5 | T26: 5.99 | V26: 0 | W26: 100 | X26: 0 | Y26: 64.3 | Z26: 0 | AA26: =SUM(C26:Z26) -> 2555.02
A27: Totale anno | B27: 2024 | C27: =SUM(C15:C26) -> 36.4 | D27: =SUM(D15:D26) -> 1128.43 | E27: =SUM(E15:E26) -> 285.8 | F27: =SUM(F15:F26) -> 66.4 | G27: =SUM(G15:G26) -> 1130.58 | H27: =SUM(H15:H26) -> 5246.62 | I27: =SUM(I15:I26) -> 294.27 | J27: =SUM(J15:J26) -> 305.08 | ... Z27: =SUM(Z15:Z26) -> 0 | AA27: =SUM(C27:Z27) -> 26073.51
A28: gennaio | B28: 2025 | C28: 6.7 | D28: 41 | E28: 19.5 | F28: 15 | G28: 261.5 | H28: 685.78 | I28: 0 | J28: 8 | K28: 1024 | L28: 95 | N28: 11.2 | O28: 15 | P28: 273.95 | Q28: 86.45 | R28: 82.75 | S28: 325 | T28: 5.99 | V28: 0 | W28: 100 | X28: 439.8 | Y28: 13.5 | Z28: 0 | AA28: =SUM(C28:Z28) -> 3510.12
A29: febbraio | B29: 2025 | C29: 14.48 | D29: 80.5 | E29: 21.6 | F29: 18 | G29: 272.33 | I29: 0 | J29: 46 | K29: 500 | L29: 150 | N29: 18.84 | Q29: 74 | R29: 91.39 | S29: 325 | T29: 5.99 | V29: 0 | W29: 100 | X29: 0 | Y29: 374.69 | Z29: 0 | AA29: =SUM(C29:Z29) -> 2092.82
A30: marzo | B30: 2025 | C30: 10 | D30: 71.1 | E30: 20 | F30: 24 | G30: 59.99 | H30: 168 | I30: 26.4 | J30: 0 | K30: 520 | L30: 138.97 | M30: 0 | O30: 18 | Q30: 10 | R30: 600.89 | S30: 0 | T30: 41.99 | V30: 0 | W30: 100 | X30: 0 | Y30: 93.3 | Z30: 0 | AA30: =SUM(C30:Z30) -> 1902.64
A31: aprile | B31: 2025 | C31: 11.6 | D31: 135.81 | E31: 0 | F31: 22.6 | G31: 0 | H31: 688.92 | I31: 9.2 | J31: 522.5 | K31: 500 | L31: 105.58 | O31: 15 | P31: 70 | Q31: 26 | R31: 34.48 | S31: 325 | T31: 5.99 | V31: 0 | W31: 100 | X31: 0 | Y31: 32.7 | Z31: 0 | AA31: =SUM(C31:Z31) -> 2605.38
A32: maggio | B32: 2025 | C32: 23 | D32: 112.75 | E32: 37.65 | F32: 43.9 | G32: 94.98 | H32: 699 | I32: 82.69 | J32: 26.5 | K32: 759.5 | L32: 202.44 | N32: 20 | P32: 154.98 | Q32: 23 | R32: 115.93 | S32: 325 | T32: 5.99 | V32: 0 | W32: 100 | X32: 0 | Z32: 0 | AA32: =SUM(C32:Z32) -> 2827.31
A33: giugno | B33: 2025 | C33: 4.4 | D33: 130.3 | E33: 19.5 | F33: 11.4 | G33: 74 | H33: 64.48 | I33: 0 | J33: 31 | K33: 500 | N33: 10 | O33: 18 | P33: 25.35 | R33: 510.17 | S33: 325 | T33: 5.99 | V33: 0 | W33: 100 | X33: 0 | Z33: 0 | AA33: =SUM(C33:Z33) -> 1829.59
A34: luglio | B34: 2025 | C34: 9 | D34: 142 | E34: 0 | F34: 13.5 | G34: 224.9 | H34: 396 | I34: 209.28 | J34: 6 | K34: 501.8 | L34: 226.97 | N34: 20 | O34: 18 | R34: 96.01 | S34: 225 | T34: 5.99 | V34: 0 | W34: 100 | X34: 0 | Y34: 414.74 | Z34: 0 | AA34: =SUM(C34:Z34) -> 2609.19
A35: agosto | B35: 2025 | C35: 13 | D35: 59 | E35: 0 | F35: 15.3 | G35: 280.5 | H35: 101.38 | I35: 0 | J35: 5 | K35: 500 | L35: 65.7 | N35: 10 | O35: 25 | P35: 23 | Q35: 2.99 | R35: 38.27 | S35: 325 | T35: 55.98 | V35: 0 | W35: 100 | X35: 0 | Y35: 0 | Z35: 0 | AA35: =SUM(C35:Z35) -> 1620.12
A36: settembre | B36: 2025 | C36: 9.4 | D36: 103.9 | E36: 50 | F36: 46.8 | G36: 0 | H36: 0 | I36: 0 | J36: 0 | K36: 1069 | L36: 142.29 | N36: 10 | O36: 0 | P36: 36.15 | R36: 170.27 | S36: 0 | T36: 5.99 | V36: 0 | W36: 100 | X36: 464.69 | Y36: 1108.34 | Z36: 0 | AA36: =SUM(C36:Z36) -> 3316.83
A37: ottobre | B37: 2025 | D37: 112.6 | E37: 12 | F37: 4.8 | G37: 54.9 | H37: 1606.26 | I37: 0 | J37: 6 | K37: 500 | L37: 149.7 | N37: 10 | O37: 21 | P37: 4 | Q37: 67.1 | R37: 396.17 | S37: 325 | T37: 5.99 | V37: 0 | W37: 100 | X37: 51.5 | Y37: 0 | Z37: 0 | AA37: =SUM(C37:Z37) -> 3427.02
A38: novembre | B38: 2025 | D38: 81.37 | E38: 0 | F38: 10.62 | G38: 96.55 | H38: 0 | I38: 0 | J38: 5 | K38: 500 | L38: 76.5 | N38: 10 | O38: 20 | Q38: 39.2 | R38: 0 | S38: 325 | T38: 5.99 | V38: 0 | W38: 100 | X38: 47.85 | Y38: 82.7 | Z38: 0 | AA38: =SUM(C38:Z38) -> 1400.78
A39: dicembre | B39: 2025 | C39: 3.2 | D39: 161.5 | E39: 0 | F39: 9 | G39: 37 | H39: 362.4 | I39: 112.3 | J39: 7 | K39: 500 | L39: 236.05 | N39: 22.84 | O39: 18 | P39: 220 | Q39: 148.9 | R39: 48.97 | S39: 325 | T39: 5.99 | V39: 0 | W39: 0 | X39: 0 | Y39: 0 | Z39: 0 | AA39: =SUM(C39:Z39) -> 2218.15
A40: Totale anno | B40: 2025 | C40: =SUM(C28:C39) -> 104.78 | D40: =SUM(D28:D39) -> 1231.83 | E40: =SUM(E28:E39) -> 180.25 | F40: =SUM(F28:F39) -> 234.92 | G40: =SUM(G28:G39) -> 1456.65 | H40: =SUM(H28:H39) -> 4772.22 | I40: =SUM(I28:I39) -> 439.87 | J40: =SUM(J28:J39) -> 663 | ... Z40: =SUM(Z28:Z39) -> 0 | AA40: =SUM(C40:Z40) -> 29359.95
...

Sheet ENTRATE
A1: MESE | B1: ANNO | C1: STIPENDIO | D1: RIPETIZIONI | E1: CEDOLE | F1: VENDITA | G1: RIMBORSI | H1: REGALI | I1: TOTALE | J1: SALDO
A2: gennaio | B2: 2023 | C2: 2456 | D2: 75 | G2: 150 | H2: 20 | I2: =SUM(C2:H2) -> 2701 | J2: =2701-148.04 -> 2552.96
A3: febbraio | B3: 2023 | C3: 1790 | D3: 30 | G3: 200 | H3: 0 | I3: =SUM(C3:H3) -> 2020 | J3: =J2+I3-SPESE!AA3 -> 743.48
A4: marzo | B4: 2023 | C4: 1715 | D4: 45 | G4: 150 | H4: 171.5 | I4: =SUM(C4:H4) -> 2081.5 | J4: =J3+I4-SPESE!AA4 -> 1750.69
A5: aprile | B5: 2023 | C5: 1697.97 | D5: 190 | G5: 150 | H5: 57.2 | I5: =SUM(C5:H5) -> 2095.17 | J5: =J4+I5-SPESE!AA5 -> 2444.18
A6: maggio | B6: 2023 | C6: 1968.3 | D6: 60 | G6: 130 | H6: 0 | I6: =SUM(C6:H6) -> 2158.3 | J6: =J5+I6-SPESE!AA6 -> 3411.11
A7: giugno | B7: 2023 | C7: 1854.7 | D7: 120 | G7: 350 | H7: 0 | I7: =SUM(C7:H7) -> 2324.7 | J7: =J6+I7-SPESE!AA7 -> 3052.07
A8: luglio | B8: 2023 | C8: 1778.87 | D8: 120 | G8: 391.39 | H8: 150 | I8: =SUM(C8:H8) -> 2440.26 | J8: =J7+I8-SPESE!AA8 -> 2617.29
A9: agosto | B9: 2023 | C9: 1758.9 | D9: 90 | G9: 0 | H9: 0 | I9: =SUM(C9:H9) -> 1848.9 | J9: =J8+I9-SPESE!AA9 -> 2431.97
A10: settembre | B10: 2023 | C10: 1793.2 | D10: 0 | G10: 41.9 | H10: 0 | I10: =SUM(C10:H10) -> 1835.1 | J10: =J9+I10-SPESE!AA10 -> 1940.84
A11: ottobre | B11: 2023 | C11: 1787 | D11: 30 | H11: 0 | I11: =SUM(C11:H11) -> 1817 | J11: =J10+I11-SPESE!AA11 -> 2195.62
A12: novembre | B12: 2023 | C12: 1792.76 | D12: 22 | G12: 85 | H12: 0 | I12: =SUM(C12:H12) -> 1899.76 | J12: =J11+I12-SPESE!AA12 -> 2841.55
A13: dicembre | B13: 2023 | C13: 3439.38 | D13: 80 | E13: 16.86 | G13: 85 | H13: 0 | I13: =SUM(C13:H13) -> 3621.24 | J13: =J12+I13-SPESE!AA13 -> 4398.28
A14: Totale anno | B14: 2023 | C14: =SUM(C2:C13) -> 23832.08 | D14: =SUM(D2:D13) -> 862 | E14: =SUM(E2:E13) -> 16.86 | F14: =SUM(F2:F13) -> 0 | G14: =SUM(G2:G13) -> 1733.29 | H14: =SUM(H2:H13) -> 398.7 | I14: =SUM(I2:I13) -> 26842.93
A15: gennaio | B15: 2024 | C15: 1797.11 | D15: 0 | G15: 0 | H15: 0 | I15: =SUM(C15:H15) -> 1797.11 | J15: =J13+I15-SPESE!AA15 -> 4276.87
A16: febbraio | B16: 2024 | C16: 1893.14 | D16: 15 | G16: 0 | H16: 0 | I16: =SUM(C16:H16) -> 1908.14 | J16: =J15+I16-SPESE!AA16 -> 4658.86
A17: marzo | B17: 2024 | C17: 1812.23 | D17: 20 | G17: 0 | H17: 0 | I17: =SUM(C17:H17) -> 1832.23 | J17: =J16+I17-SPESE!AA17 -> 4726.79
A18: aprile | B18: 2024 | C18: 1766.61 | F18: 490 | I18: =SUM(C18:H18) -> 2256.61 | J18: =J17+I18-SPESE!AA18 -> 2832.93
A19: maggio | B19: 2024 | C19: 1875.16 | D19: 15 | G19: 65 | H19: 0 | I19: =SUM(C19:H19) -> 1955.16 | J19: =J18+I19-SPESE!AA19 -> 2508.46
A20: giugno | B20: 2024 | C20: 1822.1 | D20: 20 | H20: 0 | I20: =SUM(C20:H20) -> 1842.1 | J20: =J19+I20-SPESE!AA20 -> 2940.08
A21: luglio | B21: 2024 | C21: 1881.96 | G21: 110.5 | I21: =SUM(C21:H21) -> 1992.46 | J21: =J20+I21-SPESE!AA21 -> 2742.88
A22: agosto | B22: 2024 | C22: 1820 | D22: 30 | G22: 0 | H22: 0 | I22: =SUM(C22:H22) -> 1850 | J22: =J21+I22-SPESE!AA22 -> 2986.15
A23: settembre | B23: 2024 | C23: 1821.35 | D23: 0 | H23: 0 | I23: =SUM(C23:H23) -> 1821.35 | J23: =J22+I23-SPESE!AA23 -> 2986.94
A24: ottobre | B24: 2024 | C24: 1816.55 | G24: 38 | H24: 0 | I24: =SUM(C24:H24) -> 1854.55 | J24: =J23+I24-SPESE!AA24 -> 1905.33
A25: novembre | B25: 2024 | C25: =2837.57+986 -> 3823.57 | H25: 0 | I25: =SUM(C25:H25) -> 3823.57 | J25: =J24+I25-SPESE!AA25 -> 3813.07
A26: dicembre | B26: 2024 | C26: =405.22+2372 -> 2777.22 | D26: 45 | H26: 0 | I26: =SUM(C26:H26) -> 2822.22 | J26: =J25+I26-SPESE!AA26 -> 4080.27
A27: Totale anno | B27: 2024 | C27: =SUM(C15:C26) -> 24907 | D27: =SUM(D15:D26) -> 145 | E27: =SUM(E15:E26) -> 0 | F27: =SUM(F15:F26) -> 490 | G27: =SUM(G15:G26) -> 213.5 | H27: =SUM(H15:H26) -> 0 | I27: =SUM(I15:I26) -> 25755.5
A28: gennaio | B28: 2025 | C28: 2846 | D28: 0 | G28: 211.4 | H28: 0 | I28: =SUM(C28:H28) -> 3057.4 | J28: =J26+I28-SPESE!AA28 -> 3627.55
A29: febbraio | B29: 2025 | C29: 2374 | G29: 0 | H29: 0 | I29: =SUM(C29:H29) -> 2374 | J29: =J28+I29-SPESE!AA29 -> 3908.73
A30: marzo | B30: 2025 | C30: 2443 | G30: 0 | H30: 0 | I30: =SUM(C30:H30) -> 2443 | J30: =J29+I30-SPESE!AA30 -> 4449.09
A31: aprile | B31: 2025 | C31: =257.4+2114 -> 2371.4 | D31: 80 | E31: 60 | F31: 0 | I31: =SUM(C31:H31) -> 2511.4 | J31: =J30+I31-SPESE!AA31 -> 4355.11
A32: maggio | B32: 2025 | C32: 2075 | H32: 0 | I32: =SUM(C32:H32) -> 2075 | J32: =J31+I32-SPESE!AA32 -> 3602.8
A33: giugno | B33: 2025 | C33: =2429+200 -> 2629 | H33: 0 | I33: =SUM(C33:H33) -> 2629 | J33: =J32+I33-SPESE!AA33 -> 4402.21
A34: luglio | B34: 2025 | C34: 2102 | H34: 120 | I34: =SUM(C34:H34) -> 2222 | J34: =J33+I34-SPESE!AA34 -> 4015.02
A35: agosto | B35: 2025 | C35: 772 | G35: 0 | H35: 0 | I35: =SUM(C35:H35) -> 772 | J35: =J34+I35-SPESE!AA35 -> 3166.9
A36: settembre | B36: 2025 | C36: =2062+150 -> 2212 | D36: 0 | G36: 250 | H36: 0 | I36: =SUM(C36:H36) -> 2462 | J36: =J35+I36-SPESE!AA36 -> 2312.07
A37: ottobre | B37: 2025 | C37: =2112+150 -> 2262 | D37: 20 | F37: 50 | H37: 0 | I37: =SUM(C37:H37) -> 2332 | J37: =J36+I37-SPESE!AA37 -> 1217.05
A38: novembre | B38: 2025 | C38: =2179+150 -> 2329 | H38: 0 | I38: =SUM(C38:H38) -> 2329 | J38: =J37+I38-SPESE!AA38 -> 2145.27
A39: dicembre | B39: 2025 | C39: =2767+1864 -> 4631 | G39: 56.1 | H39: 0 | I39: =SUM(C39:H39) -> 4687.1 | J39: =J38+I39-SPESE!AA39 -> 4614.22
A40: Totale anno | B40: 2025 | C40: =SUM(C28:C39) -> 29046.4 | D40: =SUM(D28:D39) -> 100 | E40: =SUM(E28:E39) -> 60 | F40: =SUM(F28:F39) -> 50 | G40: =SUM(G28:G39) -> 517.5 | H40: =SUM(H28:H39) -> 120 | I40: =SUM(I28:I39) -> 29893.9
...

Sheet Log_Dati
A1: MESE | B1: ANNO | C1: CATEGORIA | D1: NOME | E1: IMPORTO
A2: Gennaio | B2: 2023 | C2: ELISA | D2: CENA | E2: 36.4
A3: Gennaio | B3: 2023 | C3: ABBIGLIAMENTO | D3: ACG | E3: 10
A4: gennaio | B4: 2023 | C4: ABBIGLIAMENTO | D4: ARGENTINA | E4: 20
A5: gennaio | B5: 2023 | C5: ABBIGLIAMENTO | D5: PANTALONI | E5: 11
A6: gennaio | B6: 2023 | C6: ABBIGLIAMENTO | D6: STONE ISLAND | E6: 50
A7: gennaio | B7: 2023 | C7: ABBIGLIAMENTO | D7: MAGLIONE | E7: 66
A8: gennaio | B8: 2023 | C8: ABBIGLIAMENTO | D8: SCARPE | E8: 107.95
A9: gennaio | B9: 2023 | C9: ABBIGLIAMENTO | D9: CAPPOTTO | E9: 118
A10: gennaio | B10: 2023 | C10: VIAGGI | D10: SCI | E10: 381
A11: gennaio | B11: 2023 | C11: GITE | D11: PINGUINI | E11: 30
A12: febbraio | B12: 2023 | C12: ABBIGLIAMENTO | D12: PANTALONI SCI | E12: 120
A13: febbraio | B13: 2023 | C13: ABBIGLIAMENTO | D13: TORCIA | E13: 9.99
... A21: marzo | B21: 2023 | C21: ALTRO | D21: LEGO | E21: 24
A22: marzo | B22: 2023 | C22: ALTRO | E22: 8.4
A23: marzo | B23: 2023 | C23: ALTRO | D23: APE | E23: 8.5
A24: marzo | B24: 2023 | C24: ALTRO | D24: FOODSPRING | E24: 20
A25: marzo | B25: 2023 | C25: SPORT | D25: SPAL | E25: 15
A26: marzo | B26: 2023 | C26: SPORT | D26: CALZET | E26: 7
A27: marzo | B27: 2023 | C27: ABBIGLIAMENTO | D27: CUFFIE | E27: 20
A28: aprile | B28: 2023 | C28: ABBIGLIAMENTO | D28: PATEK | E28: 69.05
A29: aprile | B29: 2023 | C29: ABBIGLIAMENTO | D29: maglia | E29: 40
A30: aprile | B30: 2023 | C30: ABBIGLIAMENTO | D30: costme nike | E30: 20
A31: aprile | B31: 2023 | C31: ABBIGLIAMENTO | D31: felpa nike | E31: 21
A32: aprile | B32: 2023 | C32: ABBIGLIAMENTO | D32: pantaloni tomm | E32: 45
A33: aprile | B33: 2023 | C33: ABBIGLIAMENTO | D33: scarpe nike | E33: 49
A34: aprile | B34: 2023 | C34: ABBIGLIAMENTO | D34: camicia tommy | E34: 48
... A44: maggio | B44: 2023 | C44: ALTRO | D44: ricarica | E44: 16
A45: maggio | B45: 2023 | C45: ALTRO | E45: 5
A46: maggio | B46: 2023 | C46: ALTRO | D46: CENA CTP | E46: 28.5
A47: maggio | B47: 2023 | C47: ALTRO | D47: TORNEO | E47: 7
A48: maggio | B48: 2023 | C48: ABBIGLIAMENTO | D48: BIRKENSTOK | E48: 41.5
A49: giugno | B49: 2023 | C49: ABBIGLIAMENTO | D49: Nike ACG | E49: 125.3
A50: giugno | B50: 2023 | C50: SPORT | D50: CALCETTO | E50: 16
A51: giugno | B51: 2023 | C51: ALTRO | D51: pizza | E51: 6
A52: giugno | B52: 2023 | C52: ALTRO | D52: altro | E52: 436.1
A53: giugno | B53: 2023 | C53: ALTRO | D53: la riserva | E53: 9.3
A54: giugno | B54: 2023 | C54: ALTRO | D54: moonswatch | E54: 278.3
A55: luglio | B55: 2023 | C55: ALTRO | D55: festa | E55: 105
A56: agosto | B56: 2023 | C56: VIAGGI | D56: elba casa | E56: 332
...
